Workbook

Sheet Dashboard
A1: DEPRECIATION ANALYSIS DASHBOARD
A3: Asset Price | B3: ='Depreciation Calculator'!D8 -> 500000
A4: Scrap Value | B4: ='Depreciation Calculator'!D9 -> 50000
A5: Useful Life (Years) | B5: ='Depreciation Calculator'!D10 -> 10
A7: Method | B7: Annual Depreciation (Year 1) | C7: Total Depreciation | D7: Book Value at End of Life
A8: Straight-Line | B8: ='Depreciation Calculator'!D11 -> 45000 | C8: ='Depreciation Calculator'!D13 -> 450000 | D8: ='Depreciation Calculator'!D14 -> 50000
A9: Diminishing Balance | B9: ='Depreciation Calculator'!C26 -> 102835.88 | C9: ='Depreciation Calculator'!D20-'Depreciation Calculator'!D35 -> 450000 | D9: ='Depreciation Calculator'!D35 -> 50000
A12: Year | B12: Straight-Line Depreciation | C12: Diminishing Balance Depreciation | D12: Straight-Line Closing Value | E12: Diminishing Balance Closing Value
A13: 1 | B13: ='Depreciation Calculator'!D11 -> 45000 | C13: ='Depreciation Calculator'!C26 -> 102835.88 | D13: ='Depreciation Calculator'!D8-'Depreciation Calculator'!D11*A13 -> 455000 | E13: ='Depreciation Calculator'!D26 -> 397164.12
A14: 2 | B14: ='Depreciation Calculator'!D11 -> 45000 | C14: ='Depreciation Calculator'!C27 -> 81685.445 | D14: ='Depreciation Calculator'!D8-'Depreciation Calculator'!D11*A14 -> 410000 | E14: ='Depreciation Calculator'!D27 -> 315478.67
A15: 3 | B15: ='Depreciation Calculator'!D11 -> 45000 | C15: ='Depreciation Calculator'!C28 -> 64885.055 | D15: ='Depreciation Calculator'!D8-'Depreciation Calculator'!D11*A15 -> 365000 | E15: ='Depreciation Calculator'!D28 -> 250593.62
A16: 4 | B16: ='Depreciation Calculator'!D11 -> 45000 | C16: ='Depreciation Calculator'!C29 -> 51540.032 | D16: ='Depreciation Calculator'!D8-'Depreciation Calculator'!D11*A16 -> 320000 | E16: ='Depreciation Calculator'!D29 -> 199053.59
A17: 5 | B17: ='Depreciation Calculator'!D11 -> 45000 | C17: ='Depreciation Calculator'!C30 -> 40939.702 | D17: ='Depreciation Calculator'!D8-'Depreciation Calculator'!D11*A17 -> 275000 | E17: ='Depreciation Calculator'!D30 -> 158113.88
A18: 6 | B18: ='Depreciation Calculator'!D11 -> 45000 | C18: ='Depreciation Calculator'!C31 -> 32519.561 | D18: ='Depreciation Calculator'!D8-'Depreciation Calculator'!D11*A18 -> 230000 | E18: ='Depreciation Calculator'!D31 -> 125594.32
A19: 7 | B19: ='Depreciation Calculator'!D11 -> 45000 | C19: ='Depreciation Calculator'!C32 -> 25831.206 | D19: ='Depreciation Calculator'!D8-'Depreciation Calculator'!D11*A19 -> 185000 | E19: ='Depreciation Calculator'!D32 -> 99763.116
A20: 8 | B20: ='Depreciation Calculator'!D11 -> 45000 | C20: ='Depreciation Calculator'!C33 -> 20518.456 | D20: ='Depreciation Calculator'!D8-'Depreciation Calculator'!D11*A20 -> 140000 | E20: ='Depreciation Calculator'!D33 -> 79244.66
A21: 9 | B21: ='Depreciation Calculator'!D11 -> 45000 | C21: ='Depreciation Calculator'!C34 -> 16298.389 | D21: ='Depreciation Calculator'!D8-'Depreciation Calculator'!D11*A21 -> 95000 | E21: ='Depreciation Calculator'!D34 -> 62946.271
A22: 10 | B22: ='Depreciation Calculator'!D11 -> 45000 | C22: ='Depreciation Calculator'!C35 -> 12946.271 | D22: ='Depreciation Calculator'!D8-'Depreciation Calculator'!D11*A22 -> 50000 | E22: ='Depreciation Calculator'!D35 -> 50000

Sheet Depreciation Calculator
C2: Coachx.live
C3: Depreciation Calculator
B5: Straight Line Method
B6: Asset Cost | D6: 450000
B7: Additonal Asset Cost | D7: 50000
B8: Asset Price | D8: =D6+D7 -> 500000
B9: Scrap Value | D9: 50000
B10: Estimated Life Span (Years) | D10: 10
B11: Depreciation / Year as per Straight Line Method | D11: =IF(OR(D8="",D10=0),"",(D8-D9)/D10) -> 45000
B12: Depreciation Percentage | D12: =IFERROR(D11/D8,"") -> 0.09
B13: Total Depreciation For Its Life Span | D13: =IF(D8="","",D11*D10) -> 450000
B14: Depreciated Book Value After Its Life Span | D14: =IF(D8="","",D8-D13) -> 50000
B15: Balance Amount | D15: =IF(D8="","",D14-D9) -> 0
B17: Diminishing Balance Method
B18: Asset Cost | D18: 450000
B19: Additonal Asset Cost | D19: 50000
B20: Asset Price | D20: =D18+D19 -> 500000
B21: Scrap Value | D21: 50000
B22: Estimated Life Span (Years) | D22: 10
B23: Rate of Depreciation as per Diminishing Balance Method | D23: =IFERROR(1-(D21/D20)^(1/D22),"") -> 0.20567177
B24: Depreciation Schedule
B25: Year | C25: Year on Year Depreciation Amount | D25: Book Value
B26: 1 | C26: =IFERROR(IF($D$20>$D$21,$D$20*$D$23,0),"") -> 102835.88 | D26: =IFERROR($D$20-C26,"") -> 397164.12
B27: 2 | C27: =IFERROR(IF(D26>$D$21,D26*$D$23,0),"") -> 81685.445 | D27: =IFERROR(D26-C27,"") -> 315478.67
B28: 3 | C28: =IFERROR(IF(D27>$D$21,D27*$D$23,0),"") -> 64885.055 | D28: =IFERROR(D27-C28,"") -> 250593.62
B29: 4 | C29: =IFERROR(IF(D28>$D$21,D28*$D$23,0),"") -> 51540.032 | D29: =IFERROR(D28-C29,"") -> 199053.59
B30: 5 | C30: =IFERROR(IF(D29>$D$21,D29*$D$23,0),"") -> 40939.702 | D30: =IFERROR(D29-C30,"") -> 158113.88
B31: 6 | C31: =IFERROR(IF(D30>$D$21,D30*$D$23,0),"") -> 32519.561 | D31: =IFERROR(D30-C31,"") -> 125594.32
B32: 7 | C32: =IFERROR(IF(D31>$D$21,D31*$D$23,0),"") -> 25831.206 | D32: =IFERROR(D31-C32,"") -> 99763.116
B33: 8 | C33: =IFERROR(IF(D32>$D$21,D32*$D$23,0),"") -> 20518.456 | D33: =IFERROR(D32-C33,"") -> 79244.66
B34: 9 | C34: =IFERROR(IF(D33>$D$21,D33*$D$23,0),"") -> 16298.389 | D34: =IFERROR(D33-C34,"") -> 62946.271
B35: 10 | C35: =IFERROR(IF(D34>$D$21,D34*$D$23,0),"") -> 12946.271 | D35: =IFERROR(D34-C35,"") -> 50000
C36: =IFERROR(IF(D36>$D$21, (D36*$D$23), ""),"") | D36: =IFERROR(D35-C35, "") -> 37053.729
B37: Note: | C37: Diminishing Balance rate is calculated to reach the $50,000 scrap value at the end of 10 years.
C38: =IFERROR(IF(D38>$D$21, (D38*$D$23), ""),"") | D38: =IFERROR(D37-C37, "")
C39: =IFERROR(IF(D39>$D$21, (D39*$D$23), ""),"") | D39: =IFERROR(D38-C38, "")
C40: =IFERROR(IF(D40>$D$21, (D40*$D$23), ""),"") | D40: =IFERROR(D39-C39, "")
C41: =IFERROR(IF(D41>$D$21, (D41*$D$23), ""),"") | D41: =IFERROR(D40-C40, "")
C42: =IFERROR(IF(D42>$D$21, (D42*$D$23), ""),"") | D42: =IFERROR(D41-C41, "")
C43: =IFERROR(IF(D43>$D$21, (D43*$D$23), ""),"") | D43: =IFERROR(D42-C42, "")
...

Sheet Advanced Answers
A1: No. | B1: Question | C1: Excel formula / method | D1: Answer
A2: 1 | B2: Annual depreciation using Straight-Line | C2: =(D8-D9)/D10 -> #DIV/0! | D2: ='Depreciation Calculator'!D11 -> 45000
A3: 2 | B3: Total depreciation over useful life using Straight-Line | C3: =Annual depreciation * useful life -> #NAME? | D3: ='Depreciation Calculator'!D13 -> 450000
A4: 3 | B4: Book value after useful life using Straight-Line | C4: =Asset Price - Total depreciation -> #NAME? | D4: ='Depreciation Calculator'!D14 -> 50000
A5: 4 | B5: Rate of depreciation using Diminishing Balance | C5: =1-(Scrap Value/Asset Price)^(1/useful life) -> #NAME? | D5: ='Depreciation Calculator'!D23 -> 0.20567177
A6: 5 | B6: Depreciation amount in Year 2 (Diminishing Balance) | D6: ='Depreciation Calculator'!C27 -> 81685.445
A7: 6 | B7: Book value at the end of Year 4 (Diminishing Balance) | D7: ='Depreciation Calculator'!D29 -> 199053.59
A8: 7 | B8: Total depreciation over useful life (Diminishing Balance) | D8: ='Depreciation Calculator'!D20-'Depreciation Calculator'!D35 -> 450000
A9: 8 | B9: Book value after useful life (Diminishing Balance) | D9: ='Depreciation Calculator'!D35 -> 50000
A10: 9 | B10: Compare total depreciation amounts | C10: =Straight-Line Total depreciation - Diminishing Balance Total -> #NAME? | D10: ='Depreciation Calculator'!D13-('Depreciation Calculator'!D20-'Depreciation Calculator'!D35) -> 0
A11: 10 | B11: Presentation with visual graphs | C11: See companion PowerPoint presentation | D11: Completed
A13: Assumptions used | B13: Asset cost $450,000; additional cost $50,000; total asset price $500,000; scrap value $50,000; useful life 10 years.
A14: Important | B14: The uploaded workbook uses $50,000 scrap value in both methods. The screenshot showed $0 in the Straight-Line section; the workbook's actual input has been retained for consistency.
